{
 "cells": [
  {
   "cell_type": "markdown",
   "metadata": {},
   "source": [
    "# Introducción\n",
    "\n",
    "Incluso el código mejor escrito contendrá errores. Los errores pueden producirse debido a actualizaciones, archivos movidos u otros cambios inesperados. Afortunadamente, Python ofrece una amplia compatibilidad para el seguimiento y el control de errores.\n",
    "\n",
    "## Escenario: Creación de un programa de cohetes\n",
    "\n",
    "Imagina que es un desarrollador que está creando un programa para un cohete. El programa debe leer un archivo de configuración para asegurarse de que se carga la configuración adecuada. La lectura del archivo puede producir un error si falta el archivo o tiene otros problemas. En este módulo, explorarás cómo crear el programa.\n",
    "\n",
    "## ¿Qué descubrirás?\n",
    "Al término de este módulo, sabrás hacer lo siguiente:\n",
    "\n",
    "* Leer y usar la salida de errores de las excepciones\n",
    "Controlar correctamente las excepciones\n",
    "* Generar excepciones con mensajes de error útiles\n",
    "* Usar excepciones para controlar el flujo de un programa\n",
    "\n",
    "## ¿Cuál es el objetivo principal?\n",
    "En este módulo, descubrirás cómo usar la salida de excepción para la depuración, cómo detectar y generar excepciones, y cómo afecta a la lógica de un programa cuando se producen excepciones."
   ]
  },
  {
   "cell_type": "markdown",
   "metadata": {},
   "source": [
    "## Uso de tracebacks para buscar errores\n",
    "\n",
    "Las excepciones en Python son una característica principal del lenguaje. Es posible que te sorprenda leer que algo que genera errores se resalta como una característica. Esta sorpresa puede deberse a que las herramientas de software sólidas no parecen bloquearse con un traceback *seguimiento* (varias líneas de texto que indican cómo se inició y finalizó el error).\n",
    "\n",
    "Sin embargo, las excepciones son útiles porque ayudan en la toma de decisiones generando mensajes de error descriptivos. Pueden ayudarte a controlar los problemas esperados e inesperados.\n",
    "\n",
    "## Tracebacks\n",
    "Un traceback es el cuerpo del texto que puede apuntar al origen (y al final) de un error no controlado. Comprender los componentes de un traceback hará que seas más eficaz al corregir errores o depurar un programa que no funciona bien.\n",
    "\n",
    "La primera vez que encuentres excepciones en Python podrías verte tentado/a a evitar el error suprimiéndolo. Cuando un programa sufre un error no controlado, aparece un traceback como salida. Como verás en este módulo, los tracebacks son útiles. Hay maneras de controlar correctamente los errores para que no aparezcan o muestren información útil.\n",
    "\n",
    "Si intentamos en un notebook, abrir un archivo inexistente sucede lo siguiente:"
   ]
  },
  {
   "cell_type": "code",
   "execution_count": 1,
   "metadata": {},
   "outputs": [
    {
     "ename": "FileNotFoundError",
     "evalue": "[Errno 2] No such file or directory: '/path/to/mars.jpg'",
     "output_type": "error",
     "traceback": [
      "\u001b[1;31m---------------------------------------------------------------------------\u001b[0m",
      "\u001b[1;31mFileNotFoundError\u001b[0m                         Traceback (most recent call last)",
      "\u001b[1;32m~\\AppData\\Local\\Temp/ipykernel_6296/1885002757.py\u001b[0m in \u001b[0;36m<module>\u001b[1;34m\u001b[0m\n\u001b[1;32m----> 1\u001b[1;33m \u001b[0mopen\u001b[0m\u001b[1;33m(\u001b[0m\u001b[1;34m\"/path/to/mars.jpg\"\u001b[0m\u001b[1;33m)\u001b[0m\u001b[1;33m\u001b[0m\u001b[1;33m\u001b[0m\u001b[0m\n\u001b[0m",
      "\u001b[1;31mFileNotFoundError\u001b[0m: [Errno 2] No such file or directory: '/path/to/mars.jpg'"
     ]
    }
   ],
   "source": [
    "open(\"/path/to/mars.jpg\")"
   ]
  },
  {
   "cell_type": "markdown",
   "metadata": {},
   "source": [
    "Esa salida tiene varias partes clave. En primer lugar, el traceback menciona el orden de la salida. Después, informa de que el archivo es `stdin` (entrada en el terminal interactivo) en la primera línea de la entrada. El error es `FileNotFoundError` (el nombre de excepción), lo que significa que el archivo no existe o quizás el directorio correspondiente no existe.\n",
    "\n",
    "Es mucha información. Puede ser difícil entender por qué la línea 1 es significativa o qué significa `Errno 2`."
   ]
  },
  {
   "cell_type": "markdown",
   "metadata": {},
   "source": [
    "Intentemos crear un archivo de Python y asígnarle el nombre *open.py*, con el contenido siguiente:"
   ]
  },
  {
   "cell_type": "code",
   "execution_count": 2,
   "metadata": {},
   "outputs": [
    {
     "ename": "FileNotFoundError",
     "evalue": "[Errno 2] No such file or directory: '/path/to/mars.jpg'",
     "output_type": "error",
     "traceback": [
      "\u001b[1;31m---------------------------------------------------------------------------\u001b[0m",
      "\u001b[1;31mFileNotFoundError\u001b[0m                         Traceback (most recent call last)",
      "\u001b[1;32m~\\AppData\\Local\\Temp/ipykernel_6296/994357274.py\u001b[0m in \u001b[0;36m<module>\u001b[1;34m\u001b[0m\n\u001b[0;32m      3\u001b[0m \u001b[1;33m\u001b[0m\u001b[0m\n\u001b[0;32m      4\u001b[0m \u001b[1;32mif\u001b[0m \u001b[0m__name__\u001b[0m \u001b[1;33m==\u001b[0m \u001b[1;34m'__main__'\u001b[0m\u001b[1;33m:\u001b[0m\u001b[1;33m\u001b[0m\u001b[1;33m\u001b[0m\u001b[0m\n\u001b[1;32m----> 5\u001b[1;33m     \u001b[0mmain\u001b[0m\u001b[1;33m(\u001b[0m\u001b[1;33m)\u001b[0m\u001b[1;33m\u001b[0m\u001b[1;33m\u001b[0m\u001b[0m\n\u001b[0m",
      "\u001b[1;32m~\\AppData\\Local\\Temp/ipykernel_6296/994357274.py\u001b[0m in \u001b[0;36mmain\u001b[1;34m()\u001b[0m\n\u001b[0;32m      1\u001b[0m \u001b[1;32mdef\u001b[0m \u001b[0mmain\u001b[0m\u001b[1;33m(\u001b[0m\u001b[1;33m)\u001b[0m\u001b[1;33m:\u001b[0m\u001b[1;33m\u001b[0m\u001b[1;33m\u001b[0m\u001b[0m\n\u001b[1;32m----> 2\u001b[1;33m     \u001b[0mopen\u001b[0m\u001b[1;33m(\u001b[0m\u001b[1;34m\"/path/to/mars.jpg\"\u001b[0m\u001b[1;33m)\u001b[0m\u001b[1;33m\u001b[0m\u001b[1;33m\u001b[0m\u001b[0m\n\u001b[0m\u001b[0;32m      3\u001b[0m \u001b[1;33m\u001b[0m\u001b[0m\n\u001b[0;32m      4\u001b[0m \u001b[1;32mif\u001b[0m \u001b[0m__name__\u001b[0m \u001b[1;33m==\u001b[0m \u001b[1;34m'__main__'\u001b[0m\u001b[1;33m:\u001b[0m\u001b[1;33m\u001b[0m\u001b[1;33m\u001b[0m\u001b[0m\n\u001b[0;32m      5\u001b[0m     \u001b[0mmain\u001b[0m\u001b[1;33m(\u001b[0m\u001b[1;33m)\u001b[0m\u001b[1;33m\u001b[0m\u001b[1;33m\u001b[0m\u001b[0m\n",
      "\u001b[1;31mFileNotFoundError\u001b[0m: [Errno 2] No such file or directory: '/path/to/mars.jpg'"
     ]
    }
   ],
   "source": [
    "def main():\n",
    "    open(\"/path/to/mars.jpg\")\n",
    "\n",
    "if __name__ == '__main__':\n",
    "    main()"
   ]
  },
  {
   "cell_type": "markdown",
   "metadata": {},
   "source": [
    "La salida de error tiene más sentido ahora. Las rutas de acceso apuntan a un único archivo denominado *open.py*. La salida menciona que el error se inicia en la línea 5, que incluye la llamada a `main()`. A continuación, la salida sigue el error a la línea 2 en la llamada de función `open()`. Y, por último, `FileNotFoundError` notifica de nuevo que el archivo o el directorio no existen.\n",
    "\n",
    "Los tracebacks casi siempre incluyen la información siguiente:\n",
    "\n",
    "* Todas las rutas de acceso de archivo implicadas, para cada llamada a cada función.\n",
    "* Los números de línea asociados a cada ruta de acceso de archivo.\n",
    "* Los nombres de las funciones, métodos o clases implicados en la generación de una excepción.\n",
    "* El nombre de la excepción que se ha producido."
   ]
  },
  {
   "cell_type": "markdown",
   "metadata": {},
   "source": [
    "## Controlando las excepciones\n",
    "\n",
    "Cuando encuentres por primera vez excepciones que muestren tracebacks grandes como salida, es posible que te veas tentado/a a detectar todos los errores para evitar que esto suceda.\n",
    "\n",
    "Si estás en una misión a Marte, ¿Qué podrías hacer si un texto del sistema de navegación dice 'Se ha producido un error'? Imagina que no hay ninguna más información ni contexto, simplemente una luz roja parpadeante con el texto del error. Como desarrollador, resulta útil ponerse al otro lado del programa: ¿Qué puede hacer un usuario cuando se produce un error?\n",
    "\n",
    "Aunque en este módulo se explica cómo controlar las excepciones detectándolas, no es necesario detectar las excepciones todo el tiempo. A veces resulta útil permitir que se puedan generar excepciones para que otros autores de llamadas puedan tratar los errores.\n",
    "\n",
    "### Try y Except de los bloques\n",
    "Vamos a usar el ejemplo de navegador a fin de crear código que abra archivos de configuración para la misión de Marte. Los archivos de configuración pueden tener todo tipo de problemas, por lo que es fundamental notificarlos con precisión cuando se presenten. Sabemos que, si no existe un archivo o directorio, se genera `FileNotFoundError`. Si queremos controlar esa excepción, podemos hacerlo con un bloque try y except:\n"
   ]
  },
  {
   "cell_type": "code",
   "execution_count": 3,
   "metadata": {},
   "outputs": [
    {
     "name": "stdout",
     "output_type": "stream",
     "text": [
      "No se encontró el archivo config.txt!\n"
     ]
    }
   ],
   "source": [
    "try:\n",
    "    open('config.txt')\n",
    "except FileNotFoundError:\n",
    "    print(\"No se encontró el archivo config.txt!\")"
   ]
  },
  {
   "cell_type": "markdown",
   "metadata": {},
   "source": [
    "Después de la palabra clave `try`, agregamos código que tenga la posibilidad de producir una excepción. A continuación, agregamos la palabra clave `except` junto con la posible excepción, seguida de cualquier código que deba ejecutarse cuando se produce esa condición. Puesto que config.txt no existe en el sistema, Python imprime que el archivo de configuración no está ahí. El bloque `try` y `except`, junto con un mensaje útil, evita un seguimiento y sigue informando al usuario sobre el problema.\n",
    "\n",
    "Aunque es común un archivo que no existe, no es el único error que podemos encontrar. Los permisos de archivo no válidos pueden impedir la lectura de un archivo, incluso si este existe. Vamos a crear un archivo de Python denominado config.py. El archivo tiene código que busca y lee el archivo de configuración del sistema de navegación:"
   ]
  },
  {
   "cell_type": "code",
   "execution_count": 5,
   "metadata": {},
   "outputs": [
    {
     "name": "stdout",
     "output_type": "stream",
     "text": [
      "Couldn't find the config.txt file!\n"
     ]
    }
   ],
   "source": [
    "def main():\n",
    "    try:\n",
    "        configuration = open('config.txt')\n",
    "    except FileNotFoundError:\n",
    "        print(\"Couldn't find the config.txt file!\")\n",
    "\n",
    "if __name__ == '__main__':\n",
    "    main()"
   ]
  },
  {
   "cell_type": "markdown",
   "metadata": {},
   "source": [
    "Una manera poco útil de controlar este error sería detectar todas las excepciones posibles para evitar un traceback. Para comprender por qué detectar todas las excepciones es problemático, probaremos actualizando la función `main()`:"
   ]
  },
  {
   "cell_type": "code",
   "execution_count": 10,
   "metadata": {},
   "outputs": [],
   "source": [
    "def main():\n",
    "    try:\n",
    "        configuration = open('config.txt')\n",
    "    except Exception:\n",
    "        print(\"Couldn't find the config.txt file!\")"
   ]
  },
  {
   "cell_type": "code",
   "execution_count": 23,
   "metadata": {},
   "outputs": [
    {
     "name": "stderr",
     "output_type": "stream",
     "text": [
      "python: can't open file 'c:\\\\Users\\\\Luis\\\\Documents\\\\KATAS\\\\Proyectos\\\\CursoIntroPython\\\\config.py': [Errno 2] No such file or directory\n"
     ]
    }
   ],
   "source": [
    "!python config.py"
   ]
  },
  {
   "cell_type": "code",
   "execution_count": 24,
   "metadata": {},
   "outputs": [
    {
     "name": "stdout",
     "output_type": "stream",
     "text": [
      "Couldn't find the config.txt file!\n"
     ]
    }
   ],
   "source": [
    "!python config.py"
   ]
  },
  {
   "cell_type": "markdown",
   "metadata": {},
   "source": [
    "El problema ahora es que el mensaje de error es incorrecto. El archivo existe, pero tiene permisos diferentes y Python no puede leerlo. Cuando se trata con errores de software, puede resultar frustrante tener errores que hagan lo siguiente:\n",
    "\n",
    "* No indiquen cuál es el problema real.\n",
    "* Proporcionen una salida que no coincida con el problema real.\n",
    "* No sugieran lo que se puede hacer para corregir el problema.\n",
    "\n",
    "Vamos a corregir este fragmento de código para abordar todas estas frustraciones. Revertiremos la detección de `FileNotFoundError` y luego agregamos otro bloque `except` para detectar `PermissionError`:"
   ]
  },
  {
   "cell_type": "code",
   "execution_count": 30,
   "metadata": {},
   "outputs": [],
   "source": [
    "def main():\n",
    "    try:\n",
    "        configuration = open('config.txt')\n",
    "    except FileNotFoundError:\n",
    "        print(\"Couldn't find the config.txt file!\")\n",
    "    except IsADirectoryError:\n",
    "        print(\"Found config.txt but it is a directory, couldn't read it\")"
   ]
  }
 ],
 "metadata": {
  "interpreter": {
   "hash": "bfb0031bea809bc9b72d781f457a11d5061eebf910e4b02b19e11204d7edcf59"
  },
  "kernelspec": {
   "display_name": "Python 3.10.1 64-bit",
   "language": "python",
   "name": "python3"
  },
  "language_info": {
   "codemirror_mode": {
    "name": "ipython",
    "version": 3
   },
   "file_extension": ".py",
   "mimetype": "text/x-python",
   "name": "python",
   "nbconvert_exporter": "python",
   "pygments_lexer": "ipython3",
   "version": "3.10.1"
  },
  "orig_nbformat": 4
 },
 "nbformat": 4,
 "nbformat_minor": 2
}
